
Traceback (most recent call last):
  File "/home/mtrautne/miniconda3/lib/python3.9/site-packages/scipy/io/matlab/mio.py", line 39, in _open_file
    return open(file_like, mode), True
FileNotFoundError: [Errno 2] No such file or directory: '/groups/astuart/mtrautne/learnHomData/mat_data/smooth_res_data/smooth_/data_info.mat'

During handling of the above exception, another exception occurred:

Traceback (most recent call last):
  File "/central/home/mtrautne/LearningHomogenization/trainModels/util/preprocess_mat_to_pkl.py", line 57, in <module>
    convert_data(mat_data_dir,pkl_dir,data_name,N_data,small_dataset)
  File "/central/home/mtrautne/LearningHomogenization/trainModels/util/preprocess_mat_to_pkl.py", line 18, in convert_data
    info_in_mat = scipy.io.loadmat(info_path)
  File "/home/mtrautne/miniconda3/lib/python3.9/site-packages/scipy/io/matlab/mio.py", line 224, in loadmat
    with _open_file_context(file_name, appendmat) as f:
  File "/home/mtrautne/miniconda3/lib/python3.9/contextlib.py", line 119, in __enter__
    return next(self.gen)
  File "/home/mtrautne/miniconda3/lib/python3.9/site-packages/scipy/io/matlab/mio.py", line 17, in _open_file_context
    f, opened = _open_file(file_like, appendmat, mode)
  File "/home/mtrautne/miniconda3/lib/python3.9/site-packages/scipy/io/matlab/mio.py", line 45, in _open_file
    return open(file_like, mode), True
FileNotFoundError: [Errno 2] No such file or directory: '/groups/astuart/mtrautne/learnHomData/mat_data/smooth_res_data/smooth_/data_info.mat'
